<?xml version="1.0" ?>
<!-- =================================================================================== -->
<!-- |    This document was autogenerated by xacro from /home/vboxuser/urdf/Diff_Drive_1.4.urdf | -->
<!-- |    EDITING THIS FILE BY HAND IS NOT RECOMMENDED                                 | -->
<!-- =================================================================================== -->
<!-- This URDF was automatically created by SolidWorks to URDF Exporter! Originally created by Stephen Brawner (brawner@gmail.com) 
     Commit Version: 1.6.0-4-g7f85cfe  Build Version: 1.6.7995.38578
     For more information, please see http://wiki.ros.org/sw_urdf_exporter -->
<robot name="Diff_Drive_1.4">
  <link name="base_link_diff">
    <inertial>
      <origin rpy="0 0 0" xyz="-3.1183E-17 -3.4795E-17 0.095859"/>
      <mass value="285.23"/>
      <inertia ixx="14.835" ixy="7.0897E-16" ixz="2.2616E-15" iyy="28.56" iyz="1.454E-15" izz="28.351"/>
    </inertial>
    <visual>
      <origin rpy="0 0 0" xyz="0 0 0"/>
      <geometry>
        <mesh filename="package://diff_drivebot/meshes/visual/base_link_diff.dae"/>
      </geometry>
      <material name="">
        <color rgba="0.79216 0.81961 0.93333 1"/>
      </material>
    </visual>
    <collision>
      <origin rpy="0 0 0" xyz="0 0 0"/>
      <geometry>
        <mesh filename="package://diff_drivebot/meshes/collision/base_link_diff.STL"/>
      </geometry>
    </collision>
  </link>
  <link name="LFW">
    <inertial>
      <origin rpy="0 0 0" xyz="0 0.04 0.00011127"/>
      <mass value="4.5176"/>
      <inertia ixx="0.023236" ixy="-3.6244E-18" ixz="0" iyy="0.041693" iyz="1.3687E-18" izz="0.023276"/>
    </inertial>
    <visual>
      <origin rpy="0 0 0" xyz="0 0 0"/>
      <geometry>
        <mesh filename="package://diff_drivebot/meshes/visual/LFW.dae"/>
      </geometry>
      <material name="">
        <color rgba="0.79216 0.81961 0.93333 1"/>
      </material>
    </visual>
    <collision>
      <origin rpy="0 0 0" xyz="0 0 0"/>
      <geometry>
        <mesh filename="package://diff_drivebot/meshes/collision/LFW.STL"/>
      </geometry>
    </collision>
  </link>
  <joint name="J1" type="continuous">
    <origin rpy="0 0.17095 0" xyz="-0.315 0.22 -0.14756"/>
    <parent link="base_link_diff"/>
    <child link="LFW"/>
    <axis xyz="0 1 0"/>
  </joint>
  <link name="LRW">
    <inertial>
      <origin rpy="0 0 0" xyz="0 0.04 0.00011127"/>
      <mass value="4.5176"/>
      <inertia ixx="0.023236" ixy="2.5204E-17" ixz="-2.1684E-19" iyy="0.041693" iyz="3.1904E-18" izz="0.023276"/>
    </inertial>
    <visual>
      <origin rpy="0 0 0" xyz="0 0 0"/>
      <geometry>
        <mesh filename="package://diff_drivebot/meshes/visual/LRW.dae"/>
      </geometry>
      <material name="">
        <color rgba="0.79216 0.81961 0.93333 1"/>
      </material>
    </visual>
    <collision>
      <origin rpy="0 0 0" xyz="0 0 0"/>
      <geometry>
        <mesh filename="package://diff_drivebot/meshes/collision/LRW.STL"/>
      </geometry>
    </collision>
  </link>
  <joint name="J2" type="continuous">
    <origin rpy="0 -0.10448 0" xyz="0.315 0.22 -0.14756"/>
    <parent link="base_link_diff"/>
    <child link="LRW"/>
    <axis xyz="0 1 0"/>
  </joint>
  <link name="RFW">
    <inertial>
      <origin rpy="0 0 0" xyz="-1.6653E-16 0.04 0.00011127"/>
      <mass value="4.5176"/>
      <inertia ixx="0.023236" ixy="-1.7285E-17" ixz="-2.1684E-19" iyy="0.041693" iyz="-2.8801E-17" izz="0.023276"/>
    </inertial>
    <visual>
      <origin rpy="0 0 0" xyz="0 0 0"/>
      <geometry>
        <mesh filename="package://diff_drivebot/meshes/visual/RFW.dae"/>
      </geometry>
      <material name="">
        <color rgba="0.79216 0.81961 0.93333 1"/>
      </material>
    </visual>
    <collision>
      <origin rpy="0 0 0" xyz="0 0 0"/>
      <geometry>
        <mesh filename="package://diff_drivebot/meshes/collision/RFW.STL"/>
      </geometry>
    </collision>
  </link>
  <joint name="J3" type="continuous">
    <origin rpy="0 0.0769 3.1416" xyz="-0.315 -0.22 -0.14756"/>
    <parent link="base_link_diff"/>
    <child link="RFW"/>
    <axis xyz="0 1 0"/>
  </joint>
  <link name="RRW">
    <inertial>
      <origin rpy="0 0 0" xyz="-5.5511E-17 0.04 0.00011127"/>
      <mass value="4.5176"/>
      <inertia ixx="0.023236" ixy="2.7429E-17" ixz="-1.0842E-18" iyy="0.041693" iyz="-9.0395E-19" izz="0.023276"/>
    </inertial>
    <visual>
      <origin rpy="0 0 0" xyz="0 0 0"/>
      <geometry>
        <mesh filename="package://diff_drivebot/meshes/visual/RRW.dae"/>
      </geometry>
      <material name="">
        <color rgba="0.79216 0.81961 0.93333 1"/>
      </material>
    </visual>
    <collision>
      <origin rpy="0 0 0" xyz="0 0 0"/>
      <geometry>
        <mesh filename="package://diff_drivebot/meshes/collision/RRW.STL"/>
      </geometry>
    </collision>
  </link>
  <joint name="J4" type="continuous">
    <origin rpy="0 0.12074 3.1416" xyz="0.315 -0.22 -0.14756"/>
    <parent link="base_link_diff"/>
    <child link="RRW"/>
    <axis xyz="0 1 0"/>
  </joint>
  <ros2_control name="GazeboSimSystem" type="system">
  <hardware>
   <plugin>gz_ros2_control/GazeboSimSystem</plugin>
  </hardware>
  <joint name="J1">
   <command_interface name="velocity"/>
    <param name="min">-1</param>
    <param name="max">1</param>
   <state_interface name="position"/>
   <state_interface name="velocity"/>
  </joint> 
  <joint name="J2">
   <command_interface name="velocity"/>
    <param name="min">-1</param>
    <param name="max">1</param>
   <state_interface name="position"/>
   <state_interface name="velocity"/>
  </joint> 
  <joint name="J3">
   <command_interface name="velocity"/>
    <param name="min">-1</param>
    <param name="max">1</param>
   <state_interface name="position"/>
   <state_interface name="velocity"/>
  </joint> 
  <joint name="J4">
   <command_interface name="velocity"/>
    <param name="min">-1</param>
    <param name="max">1</param>
   <state_interface name="position"/>
   <state_interface name="velocity"/>
  </joint> 
 </ros2_control>
 <gazebo>
  <plugin filename="gz_ros2_control-system" name="gz_ros2_control::GazeboSimROS2ControlPlugin">                                  
    <robotParam>robot_description</robotParam>
    <robotParam_node>robot_state_publisher</robotParam_node>
    <parameters>$(find diff_drivebot)/config/diff_control.yaml</parameters>
  </plugin>
 </gazebo> 
</robot>

