<?xml version="1.0" encoding="utf-8"?>
<!-- This URDF was automatically created by SolidWorks to URDF Exporter! Originally created by Stephen Brawner (brawner@gmail.com) 
     Commit Version: 1.6.0-4-g7f85cfe  Build Version: 1.6.7995.38578
     For more information, please see http://wiki.ros.org/sw_urdf_exporter -->
<robot
  name="TO_URDF_1.1">
  <link
    name="base_link">
    <inertial>
      <origin
        xyz="0.125 0.138349965988052 -0.175"
        rpy="0 0 0" />
      <mass
        value="6.77486725877128" />
      <inertia
        ixx="0.0513980645062783"
        ixy="-1.2255372478021E-18"
        ixz="1.78031458525141E-18"
        iyy="0.0315144067015224"
        iyz="4.97458857482161E-19"
        izz="0.0274216662343612" />
    </inertial>
    <visual>
      <origin
        xyz="0 0 0"
        rpy="0 0 0" />
      <geometry>
        <mesh
          filename="package://TO_URDF_1.1/meshes/base_link.STL" />
      </geometry>
      <material
        name="">
        <color
          rgba="0.792156862745098 0.819607843137255 0.933333333333333 1" />
      </material>
    </visual>
    <collision>
      <origin
        xyz="0 0 0"
        rpy="0 0 0" />
      <geometry>
        <mesh
          filename="package://TO_URDF_1.1/meshes/base_link.STL" />
      </geometry>
    </collision>
  </link>
  <link
    name="LFS">
    <inertial>
      <origin
        xyz="0.0078747 -0.05849 0"
        rpy="0 0 0" />
      <mass
        value="0.61195" />
      <inertia
        ixx="0.0010504"
        ixy="-2.7483E-05"
        ixz="-7.5477E-21"
        iyy="0.00058666"
        iyz="-4.6833E-20"
        izz="0.00068007" />
    </inertial>
    <visual>
      <origin
        xyz="0 0 0"
        rpy="0 0 0" />
      <geometry>
        <mesh
          filename="package://TO_URDF_1.1/meshes/LFS.STL" />
      </geometry>
      <material
        name="">
        <color
          rgba="0.79216 0.81961 0.93333 1" />
      </material>
    </visual>
    <collision>
      <origin
        xyz="0 0 0"
        rpy="0 0 0" />
      <geometry>
        <mesh
          filename="package://TO_URDF_1.1/meshes/LFS.STL" />
      </geometry>
    </collision>
  </link>
  <joint
    name="J1"
    type="continuous">
    <origin
      xyz="0 0.315 -0.04"
      rpy="1.5708 0 3.1416" />
    <parent
      link="base_link" />
    <child
      link="LFS" />
    <axis
      xyz="0 0 1" />
  </joint>
  <link
    name="LFW">
    <inertial>
      <origin
        xyz="-5.5511E-17 0.0225 2.7756E-17"
        rpy="0 0 0" />
      <mass
        value="0.50721" />
      <inertia
        ixx="0.00054363"
        ixy="-4.4347E-20"
        ixz="4.0658E-20"
        iyy="0.00091608"
        iyz="-6.7865E-20"
        izz="0.00054363" />
    </inertial>
    <visual>
      <origin
        xyz="0 0 0"
        rpy="0 0 0" />
      <geometry>
        <mesh
          filename="package://TO_URDF_1.1/meshes/LFW.STL" />
      </geometry>
      <material
        name="">
        <color
          rgba="0.79216 0.81961 0.93333 1" />
      </material>
    </visual>
    <collision>
      <origin
        xyz="0 0 0"
        rpy="0 0 0" />
      <geometry>
        <mesh
          filename="package://TO_URDF_1.1/meshes/LFW.STL" />
      </geometry>
    </collision>
  </link>
  <joint
    name="W1"
    type="continuous">
    <origin
      xyz="0.035 -0.065 0"
      rpy="0 1.2014 1.5708" />
    <parent
      link="LFS" />
    <child
      link="LFW" />
    <axis
      xyz="1 0 0" />
  </joint>
  <link
    name="LRS">
    <inertial>
      <origin
        xyz="0.0078747 -0.05849 -6.9389E-18"
        rpy="0 0 0" />
      <mass
        value="0.61195" />
      <inertia
        ixx="0.0010504"
        ixy="-2.7483E-05"
        ixz="-1.7742E-20"
        iyy="0.00058666"
        iyz="-5.7406E-20"
        izz="0.00068007" />
    </inertial>
    <visual>
      <origin
        xyz="0 0 0"
        rpy="0 0 0" />
      <geometry>
        <mesh
          filename="package://TO_URDF_1.1/meshes/LRS.STL" />
      </geometry>
      <material
        name="">
        <color
          rgba="0.79216 0.81961 0.93333 1" />
      </material>
    </visual>
    <collision>
      <origin
        xyz="0 0 0"
        rpy="0 0 0" />
      <geometry>
        <mesh
          filename="package://TO_URDF_1.1/meshes/LRS.STL" />
      </geometry>
    </collision>
  </link>
  <joint
    name="J2"
    type="continuous">
    <origin
      xyz="0 0.035 -0.04"
      rpy="1.5708 0 3.1416" />
    <parent
      link="base_link" />
    <child
      link="LRS" />
    <axis
      xyz="0 0 1" />
  </joint>
  <link
    name="LRW">
    <inertial>
      <origin
        xyz="0 0.0225 0"
        rpy="0 0 0" />
      <mass
        value="0.507206206931255" />
      <inertia
        ixx="0.000543629952666506"
        ixy="-4.18884689413118E-20"
        ixz="5.42101086242752E-20"
        iyy="0.000916077810493713"
        iyz="-4.74921995675154E-20"
        izz="0.000543629952666506" />
    </inertial>
    <visual>
      <origin
        xyz="0 0 0"
        rpy="0 0 0" />
      <geometry>
        <mesh
          filename="package://TO_URDF_1.1/meshes/LRW.STL" />
      </geometry>
      <material
        name="">
        <color
          rgba="0.792156862745098 0.819607843137255 0.933333333333333 1" />
      </material>
    </visual>
    <collision>
      <origin
        xyz="0 0 0"
        rpy="0 0 0" />
      <geometry>
        <mesh
          filename="package://TO_URDF_1.1/meshes/LRW.STL" />
      </geometry>
    </collision>
  </link>
  <joint
    name="W2"
    type="continuous">
    <origin
      xyz="0.035 -0.065 0"
      rpy="0 1.2014 1.5708" />
    <parent
      link="LRS" />
    <child
      link="LRW" />
    <axis
      xyz="1 0 0" />
  </joint>
  <link
    name="RFS">
    <inertial>
      <origin
        xyz="0.0078747 -0.05849 0"
        rpy="0 0 0" />
      <mass
        value="0.61195" />
      <inertia
        ixx="0.0010504"
        ixy="-2.7483E-05"
        ixz="7.2584E-20"
        iyy="0.00058666"
        iyz="-7.1874E-20"
        izz="0.00068007" />
    </inertial>
    <visual>
      <origin
        xyz="0 0 0"
        rpy="0 0 0" />
      <geometry>
        <mesh
          filename="package://TO_URDF_1.1/meshes/RFS.STL" />
      </geometry>
      <material
        name="">
        <color
          rgba="0.79216 0.81961 0.93333 1" />
      </material>
    </visual>
    <collision>
      <origin
        xyz="0 0 0"
        rpy="0 0 0" />
      <geometry>
        <mesh
          filename="package://TO_URDF_1.1/meshes/RFS.STL" />
      </geometry>
    </collision>
  </link>
  <joint
    name="J3"
    type="continuous">
    <origin
      xyz="0.25 0.315 -0.04"
      rpy="1.5708 0 0" />
    <parent
      link="base_link" />
    <child
      link="RFS" />
    <axis
      xyz="0 0 1" />
  </joint>
  <link
    name="RFW">
    <inertial>
      <origin
        xyz="-5.55111512312578E-17 0.0225 -2.77555756156289E-17"
        rpy="0 0 0" />
      <mass
        value="0.507206206931255" />
      <inertia
        ixx="0.000543629952666506"
        ixy="-1.0093304555782E-19"
        ixz="4.06575814682064E-20"
        iyy="0.000916077810493714"
        iyz="-4.69802858462578E-19"
        izz="0.000543629952666506" />
    </inertial>
    <visual>
      <origin
        xyz="0 0 0"
        rpy="0 0 0" />
      <geometry>
        <mesh
          filename="package://TO_URDF_1.1/meshes/RFW.STL" />
      </geometry>
      <material
        name="">
        <color
          rgba="0.792156862745098 0.819607843137255 0.933333333333333 1" />
      </material>
    </visual>
    <collision>
      <origin
        xyz="0 0 0"
        rpy="0 0 0" />
      <geometry>
        <mesh
          filename="package://TO_URDF_1.1/meshes/RFW.STL" />
      </geometry>
    </collision>
  </link>
  <joint
    name="W3"
    type="continuous">
    <origin
      xyz="0.035 -0.065 0"
      rpy="0 1.2014 1.5708" />
    <parent
      link="RFS" />
    <child
      link="RFW" />
    <axis
      xyz="1 0 0" />
  </joint>
  <link
    name="RRS">
    <inertial>
      <origin
        xyz="0.0078747 -0.05849 -1.3878E-17"
        rpy="0 0 0" />
      <mass
        value="0.61195" />
      <inertia
        ixx="0.0010504"
        ixy="-2.7483E-05"
        ixz="5.9091E-20"
        iyy="0.00058666"
        iyz="-9.7928E-20"
        izz="0.00068007" />
    </inertial>
    <visual>
      <origin
        xyz="0 0 0"
        rpy="0 0 0" />
      <geometry>
        <mesh
          filename="package://TO_URDF_1.1/meshes/RRS.STL" />
      </geometry>
      <material
        name="">
        <color
          rgba="0.79216 0.81961 0.93333 1" />
      </material>
    </visual>
    <collision>
      <origin
        xyz="0 0 0"
        rpy="0 0 0" />
      <geometry>
        <mesh
          filename="package://TO_URDF_1.1/meshes/RRS.STL" />
      </geometry>
    </collision>
  </link>
  <joint
    name="J4"
    type="continuous">
    <origin
      xyz="0.25 0.035 -0.04"
      rpy="1.5708 0 0" />
    <parent
      link="base_link" />
    <child
      link="RRS" />
    <axis
      xyz="0 0 1" />
  </joint>
  <link
    name="RRW">
    <inertial>
      <origin
        xyz="0 0.0225 0"
        rpy="0 0 0" />
      <mass
        value="0.507206206931255" />
      <inertia
        ixx="0.000543629952666506"
        ixy="8.07056014185324E-20"
        ixz="8.13151629364128E-20"
        iyy="0.000916077810493713"
        iyz="1.19094241683827E-20"
        izz="0.000543629952666506" />
    </inertial>
    <visual>
      <origin
        xyz="0 0 0"
        rpy="0 0 0" />
      <geometry>
        <mesh
          filename="package://TO_URDF_1.1/meshes/RRW.STL" />
      </geometry>
      <material
        name="">
        <color
          rgba="0.792156862745098 0.819607843137255 0.933333333333333 1" />
      </material>
    </visual>
    <collision>
      <origin
        xyz="0 0 0"
        rpy="0 0 0" />
      <geometry>
        <mesh
          filename="package://TO_URDF_1.1/meshes/RRW.STL" />
      </geometry>
    </collision>
  </link>
  <joint
    name="W4"
    type="continuous">
    <origin
      xyz="0.035 -0.065 0"
      rpy="0 1.2014 1.5708" />
    <parent
      link="RRS" />
    <child
      link="RRW" />
    <axis
      xyz="1 0 0" />
  </joint>
</robot>